<?xml version="1.0" encoding="utf-8"?>
<mujoco model="Rat Hindlimb Right">
  <compiler inertiafromgeom="auto" angle="radian" balanceinertia="true" boundmass="0.001" boundinertia="0.001">
    <lengthrange inttotal="50" useexisting="true"></lengthrange>
  </compiler>
  <default>
    <joint limited="true" damping="0.5" armature="0.1" stiffness="2"></joint>
    <geom rgba="0.8 0.6 .4 1" margin="0.001"></geom>
    <site size="0.001"></site>
    <tendon width="0.001" rgba=".95 .3 .3 1" limited="false"></tendon>
    <default class="muscle">
      <muscle ctrllimited="true" ctrlrange="0 1" ></muscle>
    </default>
    <default class="motor">
      <general gainprm="5 0 0 0 0 0 0 0 0 0"></general>
    </default>
  </default>
  <size njmax="1000" nconmax="400" nuser_jnt="1"></size>
  <worldbody>
    <geom name="floor" pos="0 0 -0.09" size="10 10 0.125" type="plane" material="MatPlane" rgba="1 1 1 1" condim="3"></geom>
    <camera name="for_video" pos="0.1 -1.4 0.02" xyaxes="1 0 0 0 1 3"/>

    <body name="spine" pos="       0     -1.0 0" quat="0.6830126 0.6830126 -0.1830131 0.1830131">
      <joint name="hip_flx_translation1" type="slide" pos="0 0 0" axis="       1        0        0" limited="true" range="-1 1" ref="0" damping="0" stiffness="0" armature="0"></joint>
      <joint name="hip_flx_translation2" type="slide" pos="0 0 0" axis="       0       1        0" limited="true" range="-0.04 0.1" ref="0" damping="0" stiffness="0" armature="0"></joint>
      <joint name="hip_flx_translation3" type="slide" pos="0 0 0" axis="       0       0       1 " limited="true" range="-0.04 1.5" ref="0" damping="0" stiffness="0" armature="0"></joint>
      <joint name="hip_flx_rot" type="hinge" pos="0 0 0" axis="       0       0       1 " limited="true" range="-0.4 0.0" ref="0" damping="0" stiffness="0" armature="0"></joint>
      <light mode="trackcom" directional="false" pos="0 0 4.0" dir="0 0 -1"></light>
      <geom name="spine" type="mesh" mesh="spine"></geom>
      <inertial pos="       0        0        0" mass="0.01" fullinertia=" 4.8e-06  4.8e-06  4.8e-06        0        0        0"></inertial>


      <body name="L_pelvis" pos="  0.005   -0.003     -0.01" quat=" 0.0 0 0.707108 0  ">
        <geom name="L_pelvis" type="mesh" mesh="L_pelvis"></geom>
        <inertial pos="       0        0        0" mass="0.0159" fullinertia="   4e-06  3.5e-06  3.5e-06        0        0        0"></inertial>
        <site name="L_Hip_ext1" pos="0.021056  0.0028983  -0.003217"></site>
        <site name="L_Hip_flx1" pos="-0.022092 0.0013009 0.000"></site>

        <body name="L_femur" pos=" 0 0 -0" quat="0.9914448 -0.1305265 0 0">
          <geom name="L_femur" type="mesh" mesh="L_femur"></geom>
          <inertial pos="       0   -0.015        0" mass="0.014141" fullinertia="1.62e-06  2.5e-07 1.62e-06        0        0        0"></inertial>
          <site name="L_Hip_ext2" pos="0.000552  -0.007969  -0.0001961"></site>
          <site name="L_Hip_flx2" pos="-0.004624 -.01523 0.000701"></site>
          <site name="L_Knee_ext1" pos="-0.00145392895126  -0.014089113889328  0" />
          <site name="L_Knee_ext2" pos="-0.00645392895126  -0.031089113889328  0" />
          <site name="L_Knee_ext3" pos="-0.005  -0.038089113889328  -0.002" />
          <site name="L_Knee_flx1" pos="0.00145392895126  -0.016089113889328  0.00" />
          <joint name="L_hip_flx" type="hinge" pos="0 0 0" axis="       0        0        1" limited="true" range="-1.072665  1.22173" ref="0"></joint>

          <body name="L_tibia" pos="  -0.0001    -0.07251  -0.0015" quat="1.0 0.0 0.0 0.0">
            <geom name="L_tibia" type="mesh" mesh="L_tibia"></geom>
            <inertial pos="       0    0.015        0" mass="0.003338" fullinertia="1.62e-06  2.5e-07 1.62e-06        0        0        0"></inertial>
            <site name="L_Knee_ext4" pos="-0.002   0.034856932063886  0" />
            <site name="L_Knee_flx2" pos="0.004505339894322   0.032856932063886  0.0" />


            <site name="L_Ankle_ext1" pos="0.003505339894322   0.022856932063886  0.0" />
            <site name="L_Ankle_flx1" pos="-0.0052505339894322   0.022856932063886  0.0" />
            <joint name="L_knee_flx" type="hinge" pos="0.003 0.038 0" axis="       0        0        -1" limited="true" range="-2.0 -1.0" ref="0"></joint>

            <body name="L_foot" pos="       0        0        0" quat="1.0 0.0 0.0 0.0">
              <geom name="L_foot" type="mesh" mesh="L_foot"></geom>
              <inertial pos="   0.007   -0.005        0" mass="0.001571" fullinertia=" 2.5e-07 1.62e-06 1.62e-06        0        0        0"></inertial>

              <site name="L_Ankle_ext2" pos=" 0.008177772979046  -0.001076102178830  -0.000251508702143" />
              <site name="L_Ankle_flx2" pos="-0.005604146904590  -0.001287973765483  0.0" />
              <joint name="L_ankle_flx" type="hinge" pos="0 0 0" axis="       0        0        -1" limited="true" range="0.2   1.4" ref="0"></joint>
            </body>

          </body>


        </body>
      </body>


    
      <body name="R_pelvis" pos="   0.005   -0.003     0.01" quat="1.0 0.0 0.0 0.0">
        <geom name="R_pelvis" type="mesh" mesh="R_pelvis"></geom>
        <inertial pos="       0        0        0" mass="0.0159" fullinertia="   4e-06  3.5e-06  3.5e-06        0        0        0"></inertial>

        <site name="R_Hip_ext1" pos="-0.021056  0.0028983  -0.003217"></site>
        <site name="R_Hip_flx1" pos="0.022092 0.0013009 0.000"></site>


        <body name="R_femur" pos="       0        0        0" quat="0.9914448 -0.1305265 0 0">
          <geom name="R_femur" type="mesh" mesh="R_femur"></geom>
          <inertial pos="       0   -0.015        0" mass="0.014141" fullinertia="1.62e-06  2.5e-07 1.62e-06        0        0        0"></inertial>
          <site name="R_Hip_ext2" pos="-0.000552  -0.007969  -0.0001961"></site>
          <site name="R_Hip_flx2" pos=".004624 -.01523 0.000701"></site>



          <site name="R_Knee_ext1" pos="0.00145392895126  -0.014089113889328  0" />
          <site name="R_Knee_ext2" pos="0.00645392895126  -0.031089113889328  0" />
          <site name="R_Knee_ext3" pos="0.005  -0.038089113889328  -0.002" />

          <site name="R_Knee_flx1" pos="-0.00145392895126  -0.016089113889328  0.00" />
          <joint name="R_hip_flx" type="hinge" pos="0 0 0" axis="       0        0        -1" limited="true" range="-1.072665  1.22173" ref="0"></joint>


          <body name="R_tibia" pos="  -0.0001    -0.07251  -0.0015" quat="1.0 0.0 0.0 0.0">
            <geom name="R_tibia" type="mesh" mesh="R_tibia"></geom>
            <inertial pos="       0    0.015        0" mass="0.003338" fullinertia="1.62e-06  2.5e-07 1.62e-06        0        0        0"></inertial>

            <site name="R_Knee_ext4" pos="0.002   0.034856932063886  0" />
            <site name="R_Knee_flx2" pos="-0.004505339894322   0.032856932063886  0.0" />
            <site name="R_Ankle_ext1" pos="-0.003505339894322   0.022856932063886  0.0" />
            <site name="R_Ankle_flx1" pos="0.0052505339894322   0.022856932063886  0.0" />
            <joint name="R_knee_flx" type="hinge" pos="-0.003 0.038 0" axis="       0        0        1" limited="true" range="-2.0 -1.0" ref="0"></joint>


            <body name="R_foot" pos="       0        0        0" quat="1.0 0.0 0.0 0.0">
              <geom name="R_foot" type="mesh" mesh="R_foot"></geom>
              <inertial pos="   0.007   -0.005        0" mass="0.001571" fullinertia=" 2.5e-07 1.62e-06 1.62e-06        0        0        0"></inertial>
              <site name="R_Ankle_ext2" pos=" -0.008177772979046  -0.001076102178830  -0.000251508702143" />
              <site name="R_Ankle_flx2" pos="0.005604146904590  -0.001287973765483  0.0" />
              <joint name="R_ankle_flx" type="hinge" pos="0 0 0" axis="       0        0        1" limited="true" range="0.2   1.4" ref="0"></joint>
            </body>

          </body>

        </body>

      </body>

    </body>



    <camera name="for_testing" pos="0 0 0" euler="0 0 0"></camera>
  </worldbody>

  <asset>
    <mesh name="spine" file="Geometry/spine.stl" scale="       1        1        1"></mesh>
    <mesh name="R_pelvis" file="Geometry/pelvis.stl" scale="       1        1        1"></mesh>
    <mesh name="R_femur" file="Geometry/femur.stl" scale="       1        1        1"></mesh>
    <mesh name="R_tibia" file="Geometry/tibia.stl" scale="       1        1        1"></mesh>
    <mesh name="R_foot" file="Geometry/foot.stl" scale="       1        1        1"></mesh>
    <mesh name="L_pelvis" file="Geometry/pelvis.stl" scale="       -1        1        1"></mesh>
    <mesh name="L_femur" file="Geometry/femur.stl" scale="       -1        1        1"></mesh>
    <mesh name="L_tibia" file="Geometry/tibia.stl" scale="       -1        1        1"></mesh>
    <mesh name="L_foot" file="Geometry/foot.stl" scale="       -1        1        1"></mesh>

    <texture name="texplane" type="2d" builtin="checker" rgb1=".8 .8 .8" rgb2=".6 .6 .6" width="100" height="100"></texture>
    <material name="MatPlane" reflectance="0.0" texture="texplane" texrepeat="15 15" texuniform="true"></material>
    <texture type="skybox" builtin="gradient" rgb1="1 1 1" rgb2="1 1 1" width="256" height="256" />
  </asset>

  <tendon>
    <spatial name="R_hip_Ext_tendon">
      <site site="R_Hip_ext1"></site>
      <site site="R_Hip_ext2"></site>
    </spatial>
    <spatial name="R_hip_Flx_tendon">
      <site site="R_Hip_flx1"></site>
      <site site="R_Hip_flx2"></site>
    </spatial>
    <spatial name="R_knee_Ext_tendon">
      <site site="R_Knee_ext1"></site>
      <site site="R_Knee_ext2"></site>
      <site site="R_Knee_ext3"></site>
      <site site="R_Knee_ext4"></site>
    </spatial>
    <spatial name="R_knee_Flx_tendon">
      <site site="R_Knee_flx1"></site>
      <site site="R_Knee_flx2"></site>
    </spatial>
    <spatial name="R_ankle_Ext_tendon">
      <site site="R_Ankle_ext1"></site>
      <site site="R_Ankle_ext2"></site>
    </spatial>
    <spatial name="R_ankle_Flx_tendon">
      <site site="R_Ankle_flx1"></site>
      <site site="R_Ankle_flx2"></site>
    </spatial>

    <spatial name="L_hip_Ext_tendon">
      <site site="L_Hip_ext1"></site>
      <site site="L_Hip_ext2"></site>
    </spatial>
    <spatial name="L_hip_Flx_tendon">
      <site site="L_Hip_flx1"></site>
      <site site="L_Hip_flx2"></site>
    </spatial>
    <spatial name="L_knee_Ext_tendon">
      <site site="L_Knee_ext1"></site>
      <site site="L_Knee_ext2"></site>
      <site site="L_Knee_ext3"></site>
      <site site="L_Knee_ext4"></site>
    </spatial>
    <spatial name="L_knee_Flx_tendon">
      <site site="L_Knee_flx1"></site>
      <site site="L_Knee_flx2"></site>
    </spatial>
    <spatial name="L_ankle_Ext_tendon">
      <site site="L_Ankle_ext1"></site>
      <site site="L_Ankle_ext2"></site>
    </spatial>
    <spatial name="L_ankle_Flx_tendon">
      <site site="L_Ankle_flx1"></site>
      <site site="L_Ankle_flx2"></site>
    </spatial>
  </tendon>

  <actuator>
    <muscle name="R_hip_Extensor" tendon="R_hip_Ext_tendon" class="muscle"/>
    <muscle name="R_hip_Flexor" tendon="R_hip_Flx_tendon" class="muscle"/>
    <muscle name="R_knee_Extensor" tendon="R_knee_Ext_tendon" class="muscle"/>
    <muscle name="R_knee_Flexor" tendon="R_knee_Flx_tendon" class="muscle"/>
    <muscle name="R_ankle_Extensor" tendon="R_ankle_Ext_tendon" class="muscle" />
    <muscle name="R_ankle_Flexor" tendon="R_ankle_Flx_tendon" class="muscle"/>

    <muscle name="L_hip_Extensor" tendon="L_hip_Ext_tendon" class="muscle"/>
    <muscle name="L_hip_Flexor" tendon="L_hip_Flx_tendon" class="muscle"/>
    <muscle name="L_knee_Extensor" tendon="L_knee_Ext_tendon" class="muscle"/>
    <muscle name="L_knee_Flexor" tendon="L_knee_Flx_tendon" class="muscle"/>
    <muscle name="L_ankle_Extensor" tendon="L_ankle_Ext_tendon" class="muscle"/>
    <muscle name="L_ankle_Flexor" tendon="L_ankle_Flx_tendon" class="muscle"/>
  </actuator>

</mujoco>